<?xml version="1.0" encoding="utf-8"?>
<!-- =================================================================================== -->
<!-- |    This document was autogenerated by xacro from niryo_ned.urdf.xacro           | -->
<!-- |    EDITING THIS FILE BY HAND IS NOT RECOMMENDED                                 | -->
<!-- =================================================================================== -->
<robot name="niryo_ned">
  <!-- Properties -->
  <!-- Links -->
  <link name="world"/>
  <joint name="joint_world" type="fixed">
    <parent link="world"/>
    <child link="base_link"/>
    <origin rpy="0 0 0" xyz="0 0 0"/>
  </joint>
  <link name="base_link">
    <inertial>
      <origin rpy="0 0 0" xyz="-0.00240796011216664 -0.00591764669105095 0.0515774030380053"/>
      <mass value="0.999243361008122"/>
      <inertia ixx="0.002" ixy="0.0" ixz="0.0" iyy="0.002" iyz="0.0" izz="0.004"/>
    </inertial>
    <visual>
      <origin rpy="0 0 0" xyz="0 0 0"/>
      <geometry>
        <mesh filename="/home/niryodev1/Bureau/Nicolas/matlab_ned/matlab-simulation-ned/ned_model/base_link.dae"/>
      </geometry>
    </visual>
    <collision>
      <origin rpy="0 0 0" xyz="0 0 0"/>
      <geometry>
        <mesh filename="/home/niryodev1/Bureau/Nicolas/matlab_ned/matlab-simulation-ned/ned_model/base_link.stl"/>
      </geometry>
    </collision>
  </link>
  <joint name="joint_1" type="revolute">
    <origin rpy="0 0 0" xyz="0 0 0.1065"/>
    <parent link="base_link"/>
    <child link="shoulder_link"/>
    <axis xyz="0 0 1"/>
    <limit effort="10.0" lower="-2.96705972839" upper="2.96705972839" velocity="2.2"/>
  </joint>
  <link name="shoulder_link">
    <inertial>
      <origin rpy="0 0 0" xyz="-0.0307310771918448 0.00581074732334248 0.0302277607274943"/>
      <mass value="0.474558968160783"/>
      <inertia ixx="0.0015" ixy="0.0" ixz="0.0" iyy="0.0015" iyz="0.0" izz="0.0015"/>
    </inertial>
    <visual>
      <origin rpy="0 0 0" xyz="0 0 0"/>
      <geometry>
        <mesh filename="/home/niryodev1/Bureau/Nicolas/matlab_ned/matlab-simulation-ned/ned_model/shoulder_link.dae"/>
      </geometry>
    </visual>
    <collision>
      <origin rpy="0 0 0" xyz="0 0 0"/>
      <geometry>
        <mesh filename="/home/niryodev1/Bureau/Nicolas/matlab_ned/matlab-simulation-ned/ned_model/shoulder_link.stl"/>
      </geometry>
    </collision>
  </link>
  <joint name="joint_2" type="revolute">
    <origin rpy="1.5707963268 -1.5707963268 0" xyz="0 0 0.065"/>
    <parent link="shoulder_link"/>
    <child link="arm_link"/>
    <axis xyz="0 0 1"/>
    <limit effort="10.0" lower="-2.09439510239" upper="0.610865238198" velocity="2.2"/>
  </joint>
  <link name="arm_link">
    <inertial>
      <origin rpy="0 0 0" xyz="0.116485160625991 -0.00141190194997476 -0.00338105503061108"/>
      <mass value="0.513332159226246"/>
      <inertia ixx="0.0015" ixy="0.0" ixz="0.0" iyy="0.0015" iyz="0.0" izz="0.0015"/>
    </inertial>
    <visual>
      <origin rpy="0 0 0" xyz="0 0 0"/>
      <geometry>
        <mesh filename="/home/niryodev1/Bureau/Nicolas/matlab_ned/matlab-simulation-ned/ned_model/arm_link.dae"/>
      </geometry>
    </visual>
    <collision>
      <origin rpy="0 0 0" xyz="0 0 0"/>
      <geometry>
        <mesh filename="/home/niryodev1/Bureau/Nicolas/matlab_ned/matlab-simulation-ned/ned_model/arm_link.stl"/>
      </geometry>
    </collision>
  </link>
  <joint name="joint_3" type="revolute">
    <origin rpy="0 0 -1.5707963268" xyz="0.221 -0.012 0"/>
    <parent link="arm_link"/>
    <child link="elbow_link"/>
    <axis xyz="0 0 1"/>
    <limit effort="7.0" lower="-1.34390352404" upper="1.5707963268" velocity="2.0"/>
  </joint>
  <link name="elbow_link">
    <inertial>
      <origin rpy="0 0 0" xyz="0.00840548736069937 0.0235132719991579 0.00139784606943909"/>
      <mass value="0.201038841892435"/>
      <inertia ixx="0.0015" ixy="0.0" ixz="0.0" iyy="0.0015" iyz="0.0" izz="0.0015"/>
    </inertial>
    <visual>
      <origin rpy="0 0 0" xyz="0 0 0"/>
      <geometry>
        <mesh filename="/home/niryodev1/Bureau/Nicolas/matlab_ned/matlab-simulation-ned/ned_model/elbow_link.dae"/>
      </geometry>
    </visual>
    <collision>
      <origin rpy="0 0 0" xyz="0 0 0"/>
      <geometry>
        <mesh filename="/home/niryodev1/Bureau/Nicolas/matlab_ned/matlab-simulation-ned/ned_model/elbow_link.stl"/>
      </geometry>
    </collision>
  </link>
  <joint name="joint_4" type="revolute">
    <origin rpy="0 1.5707963268 0" xyz="0.047 0.0325 0"/>
    <parent link="elbow_link"/>
    <child link="forearm_link"/>
    <axis xyz="0 0 1"/>
    <limit effort="7.0" lower="-2.09439510239" upper="2.09439510239" velocity="2.0"/>
  </joint>
  <link name="forearm_link">
    <inertial>
      <origin rpy="0 0 0" xyz="-0.00811345462189901 -0.000135618649565461 0.107402242790047"/>
      <mass value="0.203543862275952"/>
      <inertia ixx="0.0015" ixy="0.0" ixz="0.0" iyy="0.0015" iyz="0.0" izz="0.0015"/>
    </inertial>
    <visual>
      <origin rpy="0 0 0" xyz="0 0 0"/>
      <geometry>
        <mesh filename="/home/niryodev1/Bureau/Nicolas/matlab_ned/matlab-simulation-ned/ned_model/forearm_link.dae"/>
      </geometry>
    </visual>
    <collision>
      <origin rpy="0 0 0" xyz="0 0 0"/>
      <geometry>
        <mesh filename="/home/niryodev1/Bureau/Nicolas/matlab_ned/matlab-simulation-ned/ned_model/forearm_link.stl"/>
      </geometry>
    </collision>
  </link>
  <joint name="joint_5" type="revolute">
    <origin rpy="3.14159265359 -1.5707963268 3.14159265359" xyz="0 0 0.188"/>
    <parent link="forearm_link"/>
    <child link="wrist_link"/>
    <axis xyz="0 0 1"/>
    <limit effort="6.0" lower="-1.74532925199" upper="0.959931088597" velocity="2.0"/>
  </joint>
  <link name="wrist_link">
    <inertial>
      <origin rpy="0 0 0" xyz="-0.0193227036920796 -0.00157014407079775 0.000275751023741896"/>
      <mass value="0.0403595377880338"/>
      <inertia ixx="0.0015" ixy="0.0" ixz="0.0" iyy="0.0015" iyz="0.0" izz="0.0015"/>
    </inertial>
    <visual>
      <origin rpy="0 0 0" xyz="0 0 0"/>
      <geometry>
        <mesh filename="/home/niryodev1/Bureau/Nicolas/matlab_ned/matlab-simulation-ned/ned_model/wrist_link.dae"/>
      </geometry>
    </visual>
    <collision>
      <origin rpy="0 0 0" xyz="0 0 0"/>
      <geometry>
        <mesh filename="/home/niryodev1/Bureau/Nicolas/matlab_ned/matlab-simulation-ned/ned_model/wrist_link.stl"/>
      </geometry>
    </collision>
  </link>
  <joint name="joint_6" type="revolute">
    <origin rpy="0 1.5707963268 0" xyz="0.0197 0.00925 0"/>
    <parent link="wrist_link"/>
    <child link="hand_link"/>
    <axis xyz="0 0 1"/>
    <limit effort="5.0" lower="-2.53072741539" upper="2.53072741539" velocity="2.0"/>
  </joint>
  <link name="hand_link">
    <inertial>
      <origin rpy="0 0 0" xyz="-5.84141230982198E-10 -1.35851692194544E-05 0.00881600136229516"/>
      <mass value="0.0148769800713074"/>
      <inertia ixx="0.0015" ixy="0.0" ixz="0.0" iyy="0.0015" iyz="0.0" izz="0.0015"/>
    </inertial>
    <visual>
      <origin rpy="0 0 0" xyz="0 0 0"/>
      <geometry>
        <mesh filename="/home/niryodev1/Bureau/Nicolas/matlab_ned/matlab-simulation-ned/ned_model/hand_link.dae"/>
      </geometry>
    </visual>
    <collision>
      <origin rpy="0 0 0" xyz="0 0 0"/>
      <geometry>
        <mesh filename="/home/niryodev1/Bureau/Nicolas/matlab_ned/matlab-simulation-ned/ned_model/hand_link.stl"/>
      </geometry>
    </collision>
  </link>
  <joint name="hand_tool_joint" type="fixed">
    <parent link="hand_link"/>
    <child link="tool_link"/>
    <origin rpy="-1.5707963268 -1.5707963268 0" xyz="0 0 0.0215"/>
  </joint>
  <link name="tool_link">
    </link>
</robot>

