<robot xmlns:xacro="http://www.ros.org/wiki/xacro" name="Ned">
    <!-- Links -->


    <!-- Properties -->

    <xacro:property name="distance_hand_tool" value="0.0215"/>

    <xacro:property name="limit_low_shoulder_rotation" value="-170.0"/>
    <xacro:property name="limit_up_shoulder_rotation" value="170.0"/>
    <xacro:property name="limit_low_arm_rotation" value="-120.0"/>
    <xacro:property name="limit_up_arm_rotation" value="35.0"/>
    <xacro:property name="limit_low_elbow_rotation" value="-77.0"/>
    <xacro:property name="limit_up_elbow_rotation" value="90.0"/>
    <xacro:property name="limit_low_forearm_rotation" value="-120.0"/>
    <xacro:property name="limit_up_forearm_rotation" value="120.0"/>
    <xacro:property name="limit_low_wrist_rotation" value="-100.0"/>
    <xacro:property name="limit_up_wrist_rotation" value="55.0"/>
    <xacro:property name="limit_low_hand_rotation" value="-145.0"/>
    <xacro:property name="limit_up_hand_rotation" value="145.0"/>

    <xacro:property name="safety_pos_margin" value="0.0"/>


    <link name="base_link">
        <inertial>
            <origin xyz="-0.00240796011216664 -0.00591764669105095 0.0515774030380053"
                    rpy="0 0 0"/>
        </inertial>
        <visual>
            <origin xyz="0 0 0"
                    rpy="0 0 3.14"/>
            <geometry>
                <mesh filename="/home/niryodev1/Bureau/Nicolas/Sprint1/ned_webots/niryo/ressource/ned_DAE/base_link.dae"/>
            </geometry>
        </visual>
    </link>

    <joint name="joint_1"
           type="revolute">
        <origin xyz="0 0 0.1065"
                rpy="0 0 0"/>
        <parent link="base_link"/>
        <child link="shoulder_link"/>
        <axis xyz="0 0 1"/>
    </joint>

    <link name="shoulder_link">
        <inertial>
            <origin xyz="-0.0307310771918448 0.00581074732334248 0.0302277607274943"
                    rpy="0 0 0"/>
            <mass value="0.474558968160783"/>
            <inertia ixx="0.0015" ixy="0.0" ixz="0.0" iyy="0.0015" iyz="0.0" izz="0.0015"/>
        </inertial>
        <visual>
            <origin xyz="0 0 0"
                    rpy="0 0 0"/>
            <geometry>
                <mesh filename="/home/niryodev1/Bureau/Nicolas/Sprint1/ned_webots/niryo/ressource/ned_DAE/shoulder_link.dae"/>
            </geometry>
        </visual>
    </link>

    <joint name="joint_2"
           type="revolute">
        <origin xyz="0 0 0.065"
                rpy="0 -1.57 0"/>
        <parent link="shoulder_link"/>
        <child link="arm_link"/>
        <axis xyz="0 0 1"/>
    </joint>

    <link name="arm_link">
        <inertial>
            <origin xyz="0.116485160625991 -0.00141190194997476 -0.00338105503061108"
                    rpy="0 0 0"/>
            <mass value="0.513332159226246"/>
            <inertia ixx="0.0015" ixy="0.0" ixz="0.0" iyy="0.0015" iyz="0.0" izz="0.0015"/>
        </inertial>
        <visual>
            <origin xyz="0 0 0"
                    rpy="0 0 -1.57"/>
            <geometry>
                <mesh filename="/home/niryodev1/Bureau/Nicolas/Sprint1/ned_webots/niryo/ressource/ned_DAE/arm_link.dae"/>
            </geometry>
        </visual>
    </link>

    <joint name="joint_3"
           type="revolute">
        <origin xyz="0.221 -0.012 0"
                rpy="0 0 0"/>
        <parent link="arm_link"/>
        <child link="elbow_link"/>
        <axis xyz="0 0 1"/>
    </joint>

    <link name="elbow_link">
        <inertial>
            <origin xyz="0.00840548736069937 0.0235132719991579 0.00139784606943909"
                    rpy="0 0 0"/>
            <mass value="0.201038841892435"/>
            <inertia ixx="0.0015" ixy="0.0" ixz="0.0" iyy="0.0015" iyz="0.0" izz="0.0015"/>

        </inertial>
        <visual>
            <origin xyz="-0.01 0.03 0"
                    rpy="0 0 -1.57"/>
            <geometry>
                <mesh filename="/home/niryodev1/Bureau/Nicolas/Sprint1/ned_webots/niryo/ressource/ned_DAE/elbow_link.dae"/>
            </geometry>
        </visual>
    </link>

    <joint name="joint_4"
           type="revolute">
        <origin xyz="0.022 0.0725 0"
                rpy="-1.57 -1.57 0"/>
        <parent link="elbow_link"/>
        <child link="forearm_link"/>
        <axis xyz="0 0 1"/>
    </joint>

    <link name="forearm_link">
        <inertial>
            <origin xyz="-0.00811345462189901 -0.000135618649565461 0.107402242790047"
                    rpy="0 0 0"/>
            <mass value="0.203543862275952"/>
            <inertia ixx="0.0015" ixy="0.0" ixz="0.0" iyy="0.0015" iyz="0.0" izz="0.0015"/>
        </inertial>
        <visual>
            <origin xyz="0 0 0.02"
                    rpy="0 0 0"/>
            <geometry>
                <mesh filename="/home/niryodev1/Bureau/Nicolas/Sprint1/ned_webots/niryo/ressource/ned_DAE/forearm_link.dae"/>
            </geometry>
        </visual>
    </link>

    <joint name="joint_5"
           type="revolute">
        <origin xyz="0 0 0.188"
                rpy="-1.57 -1.57 1.57"/>
        <parent link="forearm_link"/>
        <child link="wrist_link"/>
        <axis xyz="0 0 1"/>
    </joint>

    <link name="wrist_link">
        <inertial>
            <origin xyz="-0.0193227036920796 -0.00157014407079775 0.000275751023741896"
                    rpy="0 0 0"/>
            <mass value="0.0403595377880338"/>
            <inertia ixx="0.0015" ixy="0.0" ixz="0.0" iyy="0.0015" iyz="0.0" izz="0.0015"/>
        </inertial>
        <visual>
            <origin xyz="0 0 0"
                    rpy="0 0 0"/>
            <geometry>
                <mesh filename="/home/niryodev1/Bureau/Nicolas/Sprint1/ned_webots/niryo/ressource/ned_DAE/wrist_link.dae"/>
            </geometry>
        </visual>
    </link>

    <joint name="joint_6"
           type="revolute">
        <origin xyz="0.0197 0.00925 0"
                rpy="0 1.57 0"/>
        <parent link="wrist_link"/>
        <child link="hand_link"/>
        <axis xyz="0 0 1"/>
    </joint>

    <link name="hand_link">
        <inertial>
            <origin xyz="-5.84141230982198E-10 -1.35851692194544E-05 0.00881600136229516"
                    rpy="0 0 0"/>
            <mass value="0.0148769800713074"/>
            <inertia ixx="0.0015" ixy="0.0" ixz="0.0" iyy="0.0015" iyz="0.0" izz="0.0015"/>
        </inertial>
        <visual>
            <origin xyz="0 0 0"
                    rpy="0 0 0"/>
            <geometry>
                <mesh filename="/home/niryodev1/Bureau/Nicolas/Sprint1/ned_webots/niryo/ressource/ned_DAE/hand_link.dae"/>
            </geometry>
        </visual>
    </link>

    <joint name="hand_tool_joint" type="fixed">
        <parent link="hand_link"/>
        <child link="base_gripper_1"/>
        <origin xyz="0 0 0.0215" rpy="-1.57 0 1.57"/>
    </joint>



    <link name="base_gripper_1">
        <inertial>
            <origin xyz="0.0028582 0.0022204 0.023772"
                    rpy="0 0 0"/>
            <mass value="0.001"/>
            <inertia
                    ixx="1E-06"
                    ixy="0.0"
                    ixz="0.0"
                    iyy="1E-06"
                    iyz="0.0"
                    izz="1E-06"/>
        </inertial>
        <visual>
            <origin xyz="0 0 0"
                    rpy="0 0 0"/>
            <geometry>
                <mesh
                        filename="/home/niryodev1/Bureau/Nicolas/Sprint1/ned_webots/niryo/ressource/ned_STL/base_gripper_1.stl"/>
            </geometry>
        </visual>
        <collision>
            <origin xyz="0 0 0"
                    rpy="0 0 0"/>
            <geometry>
                <mesh
                        filename="/home/niryodev1/Bureau/Nicolas/Sprint1/ned_webots/niryo/ressource/ned_STL/base_gripper_1.stl"/>
            </geometry>
        </collision>
    </link>

    <!-- Mors 1 -->
    <link
            name="mors_1">
        <inertial>
            <origin xyz="-0.0049739 0.0067393 -0.023929"
                    rpy="0 0 0"/>
            <mass value="0.0067248"/>
            <inertia
                    ixx="1.1778E-06"
                    ixy="-2.1129E-08"
                    ixz="1.0185E-07"
                    iyy="1.3054E-06"
                    iyz="1.7669E-07"
                    izz="4.3534E-07"/>
        </inertial>
        <visual>
            <origin xyz="0 0 0"
                    rpy="0 0 0"/>
            <geometry>
                <mesh
                        filename="/home/niryodev1/Bureau/Nicolas/Sprint1/ned_webots/niryo/ressource/ned_STL/mors_1.stl"/>
            </geometry>
            <material name="">
                <color rgba="0.49804 0.49804 0.49804 1"/>
            </material>
        </visual>
        <collision>
            <origin xyz="0 0 0"
                    rpy="0 0 0"/>
            <geometry>
                <mesh
                        filename="/home/niryodev1/Bureau/Nicolas/Sprint1/ned_webots/niryo/ressource/ned_STL/mors_1.stl"/>
            </geometry>
        </collision>
    </link>
    
    <joint
            name="joint_base_to_mors_1"
            type="prismatic">
        <origin xyz="0.01455 -0.0796 0.0096137"
                rpy="1.5708 0 0"/>
        <parent link="base_gripper_1"/>
        <child link="mors_1"/>
        <axis xyz="0 1 0"/>
        <limit lower="-0.01"
               upper="0.01"
               effort="1"
               velocity="5"/>
    </joint>

    <!-- Mors 2 -->
    <link
            name="mors_2">
        <inertial>
            <origin xyz="-0.0049739 -0.0067393 -0.023929"
                    rpy="0 0 0"/>
            <mass value="0.0067248"/>
            <inertia
                    ixx="1.1778E-06"
                    ixy="2.1129E-08"
                    ixz="1.0185E-07"
                    iyy="1.3054E-06"
                    iyz="-1.7669E-07"
                    izz="4.3534E-07"/>
        </inertial>
        <visual>
            <origin xyz="0 0 0"
                    rpy="0 0 0"/>
            <geometry>
                <mesh
                        filename="/home/niryodev1/Bureau/Nicolas/Sprint1/ned_webots/niryo/ressource/ned_STL/mors_2.stl"/>
            </geometry>
        </visual>
        <collision>
            <origin xyz="0 0 0"
                    rpy="0 0 0"/>
            <geometry>
                <mesh
                        filename="/home/niryodev1/Bureau/Nicolas/Sprint1/ned_webots/niryo/ressource/mors_2.stl"/>
            </geometry>
        </collision>
    </link>

    <joint name="joint_base_to_mors_2"
           type="prismatic">
        <origin xyz="0.01455 -0.0796 -0.011066"
                rpy="1.5708 0 0"/>
        <parent link="base_gripper_1"/>
        <child link="mors_2"/>
        <axis xyz="0 -1 0"/>
        <limit lower="-0.01"
               upper="0.01"
               effort="1"
               velocity="5"/>
    </joint>

</robot>
